package com.example.belajarkotlindasar

fun main(){

    println("Coba Exception Handling 1")
    try {
        val testError :Int = 10/0
        println("Contoh Error")
        println(testError)
    }catch (e: ArithmeticException){
        println("Arithmetic Exception")
    }catch (e: Exception){
        println(e)
    }finally {
        println("Pada block Finally, apapun itu yang terjadi ya tetap di print")
    }
/*----------------------------------------------------------------------------*/
    println("\nCoba Exception Handling 2")
    contohError()
}

fun contohError(){
    try{
        println("Sebelum Exception")
        throw Exception("Hayoooo masalahnya masuk ke Throw")
        println("Sesudah Exception")
    }catch (e: Exception){
        println(e)
    }finally {
        println("Masih error, tapi finally tetap muncul ya")
    }
}